Workbook

Sheet About
A1: PREMIS conformance review — 2026_011922_premis.xml
A3: Project | B3: PoC - Digital Preservation Repository Workflow
A4: Author | B4: Torsten Fratzke
A5: UUID | B5: 99c556fc-bfec-4adc-932d-e0eea9c4be36 (document identity: minted once, permanent across editions; not entered in the UUID registry, which holds repository entities only)
A6: Version | B6: v1.0
A7: Status | B7: Issued
A8: Created | B8: 2026-10-09
A9: Modified | B9: 2026-10-12
A11: Reviewed file | B11: 2026_011922_premis.xml, v1 (PoC output, events dated 2026-10-09), in the context of the full OCFL object 2026_011922 (v1–v3). F001–F059 review the v1 file; they apply equally to v2 and v3 (F064). F060–F067 and the Versions tab review the object across versions.
A12: Source package | B12: L:\Restricted\Library\09_Team\Fratzke\Projects\dol_dpr_workflow_review_packages\2026_011922\2026_011922_v3_20261009_reviewed20261012.zip — OCFL object 2026_011922 at head v3 (v1–v3), v3 committed 2026-10-09T13:14:13Z. Frozen copy, outside the Git repository. SHA-512: a55c729bf61fc96ad5010c89418e99ae299ce59b166cec9f0e24e20abff85e00f6a6816a210e2f60cd81b9bda3fd27d4f371b6d267a004f216e1506f0f14ff85 (567,687 bytes).
A13: Against | B13: PREMIS preservation metadata — profile, v0.4 (Draft, not issued), modified 2026-10-12; rule texts as in its final state of that date.
A14: Review date | B14: 2026-10-09; revised 2026-10-12.
A15: Method | B15: By inspection against the profile. Schema validity checked with lxml and xmllint against premis-v3-0.xsd (valid, F004). Byte checks: encoding, line endings, NFC, UUID versions. OCFL object checked in full: inventory and sidecars of every version, manifest against disk, PREMIS and METS digests against the inventory (F059), file digests across versions (Versions tab). Controlled values checked against the LoC Preservation Vocabularies on id.loc.gov on 2026-10-12 (Controlled values and Vocabularies tabs). The OCFL commit records (inventory user and message) are reviewed separately (2026_011922_ocfl_inventory_review.txt).
... A20: Rule text | B20: The wording of each cited rule, copied from profile v0.4: requirement ID, name, level and cardinality, then the location and the rule.
A22: Type
A23: Non-conformance | B23: Fails a requirement of the profile.
A24: Suspected defect | B24: Looks like a defect in the PoC rather than a profile gap; needs the developer's explanation.
A25: Question | B25: Cannot be judged without information the review did not have.
A26: Profile issue | B26: A problem in the profile itself, to fix in the next edition.
A28: Dependency | B28: "None — fixable now", or the open item / registry that must be settled first.
A30: Status
A31: Open | B31: Not yet addressed (default).
A32: In progress | B32: Being worked on.
A33: Fixed | B33: Fixed in the Python writer; confirm on the next PoC output.
A34: Deferred | B34: Waits on its dependency.
A35: Not accepted | B35: Disputed; reason in Response.
A36: Closed | B36: Resolved in the review itself; no action for the Python writer.
A38: Tabs
A39: Summary | B39: Counts of findings by area and type, with how many are fixable now and how many are open; calculated from the Findings sheet.
A40: Findings | B40: One row per finding, F001–F067, with the rule it is judged against, what was found, what is required, the fix, and Owner, Status and Response for the developer (columns described above).
A41: Controlled values | B41: One row per controlled value the profile writes, with @authority, @authorityURI and @valueURI as the writer is to output them, and what the PoC writes now. Copied from profile v0.4 Controlled vocabularies; @valueURIs checked against id.loc.gov on 2026-10-12. One header row, no merged cells: can be saved as CSV.
A42: Vocabularies | B42: The LoC schemes behind the controlled values, with links to id.loc.gov, the elements each governs, and notes (deprecated schemes, terms not used).
A43: Versions | B43: One column per OCFL version of 2026_011922, one row per fact: commit record, languages held, files added, changed and re-created from an unchanged source, and PREMIS events written and carried (F060–F062, F065–F067). Layer says whether a fact is read from the OCFL inventory or from premis.xml; Meaning says what it is and where it was read; Expected (profile v0.4) says what the profile requires, with the finding where the package departs from it.
A44: PREMIS counts | B44: The objects, events and agents in each version's premis.xml: what profile v0.4 expects (new in the version, and in total with everything carried from the predecessor) and what the package contains (Found), by object kind, catalogue entry and agent role, with the finding behind each difference. Totals agree with Versions rows 10 and 11.
A45: Files | B45: One row per logical path in any version of 2026_011922, with the full SHA-512 of its content in each version's inventory state ('—' where the path is not in that version), whether it is new, changed or unchanged against the previous version, and the finding that explains a change. Counts below the table agree with Versions, Files added and Files changed.
A46: Workflow | B46: Questions and issues for the workflow, found in this review, set against the developer's Workflow Documentation v2.5 (2026-10-05) and profile v0.4: where the PoC's behaviour follows from the design, or the design and the profile disagree. Findings that depend on them cite the W-number.

Sheet Summary
A1: Summary
A3: Area | B3: Non-conformance | C3: Suspected defect | D3: Question | E3: Profile issue | F3: Total | G3: Fixable now | H3: Open
A4: Root | B4: =COUNTIFS(Findings!$B:$B,$A4,Findings!$J:$J,B$3) | C4: =COUNTIFS(Findings!$B:$B,$A4,Findings!$J:$J,C$3) | D4: =COUNTIFS(Findings!$B:$B,$A4,Findings!$J:$J,D$3) | E4: =COUNTIFS(Findings!$B:$B,$A4,Findings!$J:$J,E$3) | F4: =SUM(B4:E4) | G4: =COUNTIFS(Findings!$B:$B,$A4,Findings!$K:$K,"None — fixable now") | H4: =COUNTIFS(Findings!$B:$B,$A4,Findings!$M:$M,"Open")
A5: General | B5: =COUNTIFS(Findings!$B:$B,$A5,Findings!$J:$J,B$3) | C5: =COUNTIFS(Findings!$B:$B,$A5,Findings!$J:$J,C$3) | D5: =COUNTIFS(Findings!$B:$B,$A5,Findings!$J:$J,D$3) | E5: =COUNTIFS(Findings!$B:$B,$A5,Findings!$J:$J,E$3) | F5: =SUM(B5:E5) | G5: =COUNTIFS(Findings!$B:$B,$A5,Findings!$K:$K,"None — fixable now") | H5: =COUNTIFS(Findings!$B:$B,$A5,Findings!$M:$M,"Open")
A6: Intellectual entity | B6: =COUNTIFS(Findings!$B:$B,$A6,Findings!$J:$J,B$3) | C6: =COUNTIFS(Findings!$B:$B,$A6,Findings!$J:$J,C$3) | D6: =COUNTIFS(Findings!$B:$B,$A6,Findings!$J:$J,D$3) | E6: =COUNTIFS(Findings!$B:$B,$A6,Findings!$J:$J,E$3) | F6: =SUM(B6:E6) | G6: =COUNTIFS(Findings!$B:$B,$A6,Findings!$K:$K,"None — fixable now") | H6: =COUNTIFS(Findings!$B:$B,$A6,Findings!$M:$M,"Open")
A7: Representation | B7: =COUNTIFS(Findings!$B:$B,$A7,Findings!$J:$J,B$3) | C7: =COUNTIFS(Findings!$B:$B,$A7,Findings!$J:$J,C$3) | D7: =COUNTIFS(Findings!$B:$B,$A7,Findings!$J:$J,D$3) | E7: =COUNTIFS(Findings!$B:$B,$A7,Findings!$J:$J,E$3) | F7: =SUM(B7:E7) | G7: =COUNTIFS(Findings!$B:$B,$A7,Findings!$K:$K,"None — fixable now") | H7: =COUNTIFS(Findings!$B:$B,$A7,Findings!$M:$M,"Open")
A8: File | B8: =COUNTIFS(Findings!$B:$B,$A8,Findings!$J:$J,B$3) | C8: =COUNTIFS(Findings!$B:$B,$A8,Findings!$J:$J,C$3) | D8: =COUNTIFS(Findings!$B:$B,$A8,Findings!$J:$J,D$3) | E8: =COUNTIFS(Findings!$B:$B,$A8,Findings!$J:$J,E$3) | F8: =SUM(B8:E8) | G8: =COUNTIFS(Findings!$B:$B,$A8,Findings!$K:$K,"None — fixable now") | H8: =COUNTIFS(Findings!$B:$B,$A8,Findings!$M:$M,"Open")
A9: Event | B9: =COUNTIFS(Findings!$B:$B,$A9,Findings!$J:$J,B$3) | C9: =COUNTIFS(Findings!$B:$B,$A9,Findings!$J:$J,C$3) | D9: =COUNTIFS(Findings!$B:$B,$A9,Findings!$J:$J,D$3) | E9: =COUNTIFS(Findings!$B:$B,$A9,Findings!$J:$J,E$3) | F9: =SUM(B9:E9) | G9: =COUNTIFS(Findings!$B:$B,$A9,Findings!$K:$K,"None — fixable now") | H9: =COUNTIFS(Findings!$B:$B,$A9,Findings!$M:$M,"Open")
A10: Agent | B10: =COUNTIFS(Findings!$B:$B,$A10,Findings!$J:$J,B$3) | C10: =COUNTIFS(Findings!$B:$B,$A10,Findings!$J:$J,C$3) | D10: =COUNTIFS(Findings!$B:$B,$A10,Findings!$J:$J,D$3) | E10: =COUNTIFS(Findings!$B:$B,$A10,Findings!$J:$J,E$3) | F10: =SUM(B10:E10) | G10: =COUNTIFS(Findings!$B:$B,$A10,Findings!$K:$K,"None — fixable now") | H10: =COUNTIFS(Findings!$B:$B,$A10,Findings!$M:$M,"Open")
A11: Versions | B11: =COUNTIFS(Findings!$B:$B,$A11,Findings!$J:$J,B$3) | C11: =COUNTIFS(Findings!$B:$B,$A11,Findings!$J:$J,C$3) | D11: =COUNTIFS(Findings!$B:$B,$A11,Findings!$J:$J,D$3) | E11: =COUNTIFS(Findings!$B:$B,$A11,Findings!$J:$J,E$3) | F11: =SUM(B11:E11) | G11: =COUNTIFS(Findings!$B:$B,$A11,Findings!$K:$K,"None — fixable now") | H11: =COUNTIFS(Findings!$B:$B,$A11,Findings!$M:$M,"Open")
A12: Profile | B12: =COUNTIFS(Findings!$B:$B,$A12,Findings!$J:$J,B$3) | C12: =COUNTIFS(Findings!$B:$B,$A12,Findings!$J:$J,C$3) | D12: =COUNTIFS(Findings!$B:$B,$A12,Findings!$J:$J,D$3) | E12: =COUNTIFS(Findings!$B:$B,$A12,Findings!$J:$J,E$3) | F12: =SUM(B12:E12) | G12: =COUNTIFS(Findings!$B:$B,$A12,Findings!$K:$K,"None — fixable now") | H12: =COUNTIFS(Findings!$B:$B,$A12,Findings!$M:$M,"Open")
A13: Total | B13: =SUM(B4:B12) | C13: =SUM(C4:C12) | D13: =SUM(D4:D12) | E13: =SUM(E4:E12) | F13: =SUM(F4:F12) | G13: =SUM(G4:G12) | H13: =SUM(H4:H12)
A15: Counts are of findings (rows), not of occurrences. Summary updates as Status changes on the Findings sheet. Fixable now counts findings whose Dependency is "None — fixable now"; questions closed in review carry "—".

Sheet Findings
A1: ID | B1: Area | C1: Rule(s) | D1: Rule text (from the profile) | E1: Element / location | F1: Occurrences | G1: Found | H1: Required | I1: Fix | J1: Type | K1: Dependency | L1: Owner | M1: Status | N1: Response
A2: F001 | B2: Root | C2: DPM13 | D2: DPM13 Encoding [MUST, —] metadata/preservation/{JOB_ID}_premis.xml Encoded in UTF-8 [RFC3629] without a byte-order mark, opening with the XML declaration <?xml version="1.0" encoding="UTF-8"?>; text in Unicode Normalization Form C [UAX15]; LF line endings. Values copied from other sources (DOL file names in originalName, values taken from DOME) are normalised to NFC when written. | E2: XML declaration | F2: 1 | G2: <?xml version='1.0' encoding='utf-8'?> (single quotes, lowercase encoding). CRLF line endings on all 410 lines, as committed (the file's SHA-512 0563f1ff… matches the v1 state of the OCFL inventory). No byte-order mark; text is NFC. | H2: Exactly <?xml version="1.0" encoding="UTF-8"?>; UTF-8 without BOM, NFC, LF line endings. | I2: Write the declaration line exactly as <?xml version="1.0" encoding="UTF-8"?>. The PoC output matches Python's xml.etree.ElementTree, which writes single quotes and the encoding as given; write this line explicitly, then serialise the root without a declaration. Save as UTF-8 without BOM, LF line endings, text values NFC-normalised. Open the output file with newline="\n" (Python on Windows writes CRLF in text mode otherwise). | J2: Non-conformance | K2: None — fixable now | L2: EG / implementation | M2: In progress | N2: 2026-10-15 implementation response: Exact UTF-8 declaration, no BOM, NFC text and LF are written by profile_workflow.serialize.
A3: F002 | B3: Root | C3: DPM16 | D3: DPM16 PREMIS namespace [MUST, 1..1] premis/@xmlns Declared as the default namespace, set to http://www.loc.gov/premis/v3; PREMIS elements are written without a prefix, and xsi:type values are given unprefixed (file, representation, intellectualEntity), resolving to the PREMIS types through the default namespace. Example: <premis xmlns="http://www.loc.gov/premis/v3" …>; then <object xsi:type="file"> | E3: All elements; object/@xsi:type | F3: All elements | G3: premis: prefix on every element; xsi:type values prefixed (premis:file, premis:representation). | H3: PREMIS 3 namespace declared as default; elements unprefixed; xsi:type values unprefixed (file, representation, intellectualEntity). | I3: Declare PREMIS as the default namespace on the root: <premis xmlns="http://www.loc.gov/premis/v3" …>. Write elements without prefix and xsi:type="file", "representation", "intellectualEntity". With ElementTree: ET.register_namespace("", "http://www.loc.gov/premis/v3") before serialising. | J3: Non-conformance | K3: None — fixable now | L3: EG / implementation | M3: In progress | N3: 2026-10-15 implementation response: Default PREMIS 3 namespace and unprefixed xsi:type values; official XSD validation.
A4: F003 | B4: Root | C4: DPM18, DPM19 | D4: DPM18 Schema location [MUST, 1..1] premis/@xsi:schemaLocation Set to http://www.loc.gov/premis/v3 ../../schemas/premis.xsd: the package-local copy, by its path relative to metadata/preservation/. Example: xsi:schemaLocation="http://www.loc.gov/premis/v3 ../../schemas/premis.xsd" DPM19 Local schema copy [MUST, 1..1 per package] schemas/premis.xsd A copy of the PREMIS 3.0 schema is held in the package schemas/ folder, so the PREMIS file can be validated wherever the package is, without network access, in restricted environments, and after the schema's published location has changed or disappeared (cf. [DILCIS-CSIP]). The 3.0 schema is self-contained: it imports no other schema (3.0 removed the XLink reference). Although a SIP otherwise carries only new and changed files, every SIP carries the schemas/ folder, so that the premis.xml and METS.xml it carries resolve their schemas within the bag; OCFL stores identical bytes once. The copy is the Library of Congress file https://www.loc.gov/standards/premis/v3/premis.xsd, byte-identical in every package; its SHA-512 is fixed when the pipeline is configured ([PREMIS-XSD-SHA512]; see *Open items*), and a package whose schemas/premis.xsd differs is held. | E4: premis/@xsi:schemaLocation | F4: 1 | G4: Absent. | H4: http://www.loc.gov/premis/v3 ../../schemas/premis.xsd, with the package-local copy at schemas/premis.xsd. | I4: Add to the root: xsi:schemaLocation="http://www.loc.gov/premis/v3 ../../schemas/premis.xsd". Copy the LoC PREMIS 3.0 premis.xsd into every package at schemas/premis.xsd. | J4: Non-conformance | K4: None — fixable now | L4: EG / implementation | M4: In progress | N4: 2026-10-15 implementation response: Package-local schemas/premis.xsd and relative schemaLocation; schema SHA-512 pins checked at ingest.
A5: F004 | B5: Root | C5: DPM10 | D5: DPM10 Schema validity [MUST, —] metadata/preservation/{JOB_ID}_premis.xml against schemas/premis.xsd The preparation side validates premis.xml against the package-local PREMIS 3.0 schema before bagging; the ingest side validates it again after appending its events, before commit. Validation uses only the schemas in the package's schemas/ folder (DPM18, DPM19), and also checks that the file contains no semantic unit at level NOT USED (see *Conventions*). An invalid file halts the item on the preparation side; on the ingest side it commits nothing and holds the bag. Example: a file object carrying storage is valid against the PREMIS 3.0 schema, but storage is NOT USED in this profile (DPM64), so the file fails this check. | E5: Whole file | F5: 1 | G5: Valid against the PREMIS 3.0 schema (premis-v3-0.xsd, LoC, 2016-01-18), checked with lxml on 2026-10-09. No NOT USED units present. Both halves of DPM10 pass for this file. METS and inventory agreement checked separately: F059. | H5: Validate against the package-local premis.xsd before bagging and again before commit; reject any NOT USED unit. | I5: None (closed). | J5: Question | K5: — | M5: Closed | N5: Resolved in review: schema-valid, no NOT USED units. No action for the Python writer. 2026-10-15 implementation response: Original review closure/profile issue retained; no implementation closure asserted.
A6: F005 | B6: General | C6: Controlled vocabularies; DPM91 | D6: DPM91 Event type [MUST, 1..1] event/eventType The type given in the event's catalogue entry. LoC event types carry @authority, @authorityURI and @valueURI; the one local type (DPM108) carries @authority="local" until this profile's namespace is defined (see *Open items*). Example: normalization, @valueURI http://id.loc.gov/vocabulary/preservation/eventType/nor Controlled vocabularies This section lists the controlled vocabularies used in the package PREMIS file. Only the values this profile writes are listed; a value not listed is not written. Values from [LoC-PV] carry @authority, @authorityURI and @valueURI (DPM91); local values carry @authority="local" until this profile's namespace is defined (see *Open items*), except identifier types, which are written as plain values (vocPREMISIdentifierTypes). Every @valueURI listed was checked against [LoC-PV] on 2026-10-12. A value from [LoC-PV] is written exactly as its authorised label, including case (e.g. is Included In, has Source). | E6: All controlled values | F6: Throughout | G6: No @authority, @authorityURI or @valueURI on any controlled value (eventType, relationshipType/SubType, messageDigestAlgorithm, roles, agentType). | H6: LoC values carry @authority, @authorityURI and @valueURI; local values carry @authority="local". | I6: Keep a lookup table in the Python writer, value → @valueURI, and add the three attributes to every LoC controlled value, e.g. <relationshipType authority="relationshipType" authorityURI="http://id.loc.gov/vocabulary/preservation/relationshipType" valueURI="http://id.loc.gov/vocabulary/preservation/relationshipType/str">structural</relationshipType>. Local values: authority="local". The complete lookup is the Controlled values tab of this workbook. Never use the deprecated LoC scheme Linking Agent Role (Event) (…/linkingAgentRoleEvent); agent roles come from Event Related Agent Role (…/eventRelatedAgentRole). | J6: Non-conformance | K6: None — fixable now | L6: EG / implementation | M6: In progress | N6: 2026-10-15 implementation response: Controlled-value lookup adds authority/authorityURI/valueURI; local terms use authority=local; identifier types stay plain.
A7: F006 | B7: Intellectual entity | C7: DPM20–DPM24 | D7: DPM20 Object category [MUST, 1..1] object[@xsi:type='intellectualEntity'] Exactly one per PREMIS file. DPM21 Object identification [MUST, 2..2] object/objectIdentifier Two identifiers, in this order: the UUID (DPM22, DPM23), then the JOB_ID (DPM24). DPM22 Type of identification [MUST, 1..1] object/objectIdentifier/objectIdentifierType Set to UUID in the first identifier. DPM23 Identification value [MUST, 1..1] object/objectIdentifier/objectIdentifierValue The object's UUID: a UUID version 4 [UUID] in its standard lowercase form, without prefix. The same UUID identifies the AIP and its OCFL object: it is the root METS @OBJID and the OCFL inventory id, which carry it in urn:uuid: form. This is the one case where a UUID names more than one entity; it is allowed because the intellectual entity and its AIP correspond one-to-one for the life of the object. The object folder is named by the JOB_ID (DPM24), not by this UUID. Each SIP has its own UUID (DPM8), which the SIP's root METS carries as @OBJID until the ingest side replaces it with the object's UUID at the SIP→AIP transformation. Example: 9cad434a-aedd-4955-bc53-1f1e3c1c882a DPM24 JOB_ID identifier [MUST, 1..1] object/objectIdentifier[objectIdentifierType='JOB_ID'] Second identifier: type JOB_ID, value the JOB_ID: the four-digit year, an underscore and a six-digit zero-padded number (YYYY_NNNNNN, e.g. 2026_012017). | E7: object[@xsi:type='intellectualEntity'] | F7: 1 (typed as representation; expected 1 intellectual entity) | G7: No object typed intellectualEntity. The object's UUID ec1921e0-76fd-4ab3-8b4a-0d1f105fc2ad (the root METS @OBJID and the OCFL inventory id) is written on an object typed representation, with the UUID as its only identifier. Same pattern as in 2026_009714. | H7: Exactly one, with two identifiers in order: UUID (a uuid4, the object UUID), then JOB_ID 2026_011922. Note: the same UUID also appears outside PREMIS, in urn:uuid: form, as the OCFL inventory id and the root METS @OBJID (DPM23); nothing further is written in PREMIS. | I7: Retype the existing object ec1921e0-76fd-4ab3-8b4a-0d1f105fc2ad: xsi:type="intellectualEntity". Keep its UUID (do not mint a new one: it is the object's UUID, DPM23). Add the second objectIdentifier JOB_ID 2026_011922. Pattern: Example 1 of the profile (intellectual entity block). | J7: Non-conformance | K7: None — fixable now | L7: EG / implementation | M7: In progress | N7: 2026-10-15 implementation response: One intellectualEntity retains the existing object UUID and carries UUID then JOB_ID identifiers.
A8: F007 | B8: Intellectual entity | C8: DPM25, DPM71 | D8: DPM25 Relationships [MUST, 2..2] object/relationship Representation membership, as set out in the *Relationship catalogue* (DPM71). DPM71 Representation membership [MUST, 2..2 per intellectual entity] object[@xsi:type='intellectualEntity']/relationship structural / includes, related object each representation. Example: 864aaa6f-ea0f-40d4-a83d-4be03b108e55 (rep_2) | E8: intellectualEntity/relationship | F8: 0 (expected 2) | G8: Absent (the intellectual entity is mistyped, F006). | H8: structural / includes → rep_1 and → rep_2. | I8: In the same block, after the identifiers: two relationship elements, structural / includes → [REP_1-UUID] and structural / includes → [REP_2-UUID]. | J8: Non-conformance | K8: None — fixable now | L8: EG / implementation | M8: In progress | N8: 2026-10-15 implementation response: IE includes relationships to two stable representation UUIDs.
A9: F008 | B9: Representation | C9: DPM27 | D9: DPM27 Object category [MUST, 2..2] object[@xsi:type='representation'] Exactly two per PREMIS file. | E9: object[@xsi:type='representation'] | F9: 0 (expected 2) | G9: No representations. The only object typed representation (ec1921e0-…) is the intellectual entity (F006); both the rep_1 DOCX and the rep_2 master point to it. | H9: Two representations, rep_1 (authoring sources) and rep_2 (PDF/A masters and attachments), each with its own uuid4. | I9: Write two representation objects, rep_1 and rep_2, each with a new uuid4 entered in the UUID registry. Do not reuse ec1921e0-…: it is the object's UUID (F006). The DOCX belongs to rep_1, the master to rep_2. | J9: Non-conformance | K9: None — fixable now | L9: EG / implementation | M9: In progress | N9: 2026-10-15 implementation response: Independent registered UUID4s for rep_1 and rep_2. Attachment-only jobs retain an empty rep_1: draft adaptation requiring review.
A10: F009 | B10: Representation | C10: DPM28, DPM41 | D10: DPM28 Object identification [MUST, 2..2] object/objectIdentifier Two identifiers, in this order: the UUID (DPM29, DPM30), then the filepath (DPM41). DPM41 Filepath identifier [MUST, 1..1] object/objectIdentifier[objectIdentifierType='filepath'] Type filepath. For a held file, the value is its OCFL logical path: relative to the version's content/ directory, /-separated, without version prefix (e.g. representations/rep_2/data/en/2026_012017_en.pdf). For a representation, the value is the path of its folder on the same basis (e.g. representations/rep_2); being a folder, it does not appear in the inventory state. | E10: representation/objectIdentifier | F10: 0 (no representations) | G10: No representations (F008). | H10: UUID, then filepath identifier: representations/rep_1 or representations/rep_2. | I10: On each new representation, after the UUID: <objectIdentifier><objectIdentifierType>filepath</objectIdentifierType><objectIdentifierValue>representations/rep_1</objectIdentifierValue></objectIdentifier> (rep_2 likewise). Write identifier types as plain values, without @authority (vocPREMISIdentifierTypes; F057). | J10: Non-conformance | K10: None — fixable now | L10: EG / implementation | M10: In progress | N10: 2026-10-15 implementation response: Representation identifiers are UUID then filepath.
A11: F010 | B11: Representation | C11: DPM35, DPM72, DPM73 | D11: DPM35 Relationships [MUST, 2..n] object/relationship Membership in the intellectual entity and of its files, as set out in the *Relationship catalogue* (DPM72, DPM73). DPM72 Inclusion in the intellectual entity [MUST, 1..1 per representation] object[@xsi:type='representation']/relationship structural / is Included In, related object the intellectual entity. Example: 9cad434a-aedd-4955-bc53-1f1e3c1c882a DPM73 File membership [MUST, 1..n per representation] object[@xsi:type='representation']/relationship structural / includes, related object each held file of the representation. Appended to the representation as files are added (DPM4); an includes to a file later superseded at its path is kept (see *Superseded files*). Example: 3aaa37c1-1f81-48f5-8144-cd222bfa84c7 (the English master) | E11: representation/relationship | F11: 0 | G11: No representations (F008). | H11: structural / is Included In → IE; structural / includes → each held file of that representation. | I11: On each representation: relationship structural / is Included In → [OBJECT-UUID]; then structural / includes → each held file of that representation (rep_1 → the DOCX UUID; rep_2 → the master UUID). | J11: Non-conformance | K11: None — fixable now | L11: EG / implementation | M11: In progress | N11: 2026-10-15 implementation response: Bidirectional structural includes/is Included In links; prior includes retained.
A12: F011 | B12: File | C12: DPM37–DPM39 | D12: DPM37 Object identification [MUST, 1..2] object/objectIdentifier For every file object the UUID (DPM38, DPM39); for every held file, then the filepath (DPM41), in that order. DPM38 Type of identification [MUST, 1..1] object/objectIdentifier/objectIdentifierType Set to UUID in the first identifier. DPM39 Identification value [MUST, 1..1] object/objectIdentifier/objectIdentifierValue The file's UUID (file_id in the workflow): a UUID version 4, without prefix, minted when the file first exists in the pipeline: at step 1 for files acquired from DOL (authoring sources and published PDFs), at step 3 for masters, and when produced for reports, logs and DOME. New bytes at an existing path are a new file with a new UUID (DPM8). Example: 3aaa37c1-1f81-48f5-8144-cd222bfa84c7 (the English master) | E12: file/objectIdentifier | F12: 8 file objects | G12: Only identifier is type local-path; no UUID on any file. | H12: First identifier type UUID (uuid4 minted when the file first exists in the pipeline), then the filepath identifier. | I12: Mint a uuid4 for each file when it first exists in the pipeline (step 1 for files from DOL, step 2 for the master, when produced for reports and DOME), enter it in the UUID registry, and write it as the first objectIdentifier (type UUID). The path becomes the second identifier (F012). The pipeline already assigns these: the QA report carries file_id for the master (ef1fe473-06b0-496a-9fd7-090d6388b748 in v1) and the published PDF (585992a9-deba-427d-9360-fce164e33a16). Write those, not new values. | J12: Non-conformance | K12: None — fixable now | L12: EG / implementation | M12: In progress | N12: 2026-10-15 implementation response: Existing stage file IDs are reused; new stage UUIDs enter the local registry before return. Evidence/content IDs are registered once.
A13: F012 | B13: File | C13: DPM41 | D13: DPM41 Filepath identifier [MUST, 1..1] object/objectIdentifier[objectIdentifierType='filepath'] Type filepath. For a held file, the value is its OCFL logical path: relative to the version's content/ directory, /-separated, without version prefix (e.g. representations/rep_2/data/en/2026_012017_en.pdf). For a representation, the value is the path of its folder on the same basis (e.g. representations/rep_2); being a folder, it does not appear in the inventory state. | E13: file/objectIdentifier/objectIdentifierType | F13: 8 file objects | G13: Identifier type local-path. | H13: Identifier type filepath; value the OCFL logical path. | I13: Change objectIdentifierType from local-path to filepath on all 8 file objects. The value is already the logical path relative to content/; it changes only where the path itself changes (DOME, F024; canonical names, F025). It follows the UUID identifier. | J13: Non-conformance | K13: None — fixable now | L13: EG / implementation | M13: In progress | N13: 2026-10-15 implementation response: Held files carry UUID then filepath identifiers; local-path removed in profile mode.
A14: F013 | B14: File | C14: DPM40 | D14: DPM40 Published PDF, described not held [MUST, 0..n] object[@xsi:type='file'] The published PDF from which a master is derived is described as a file object without a filepath identifier. Its UUID is the one minted for it at step 1; its fixity is the digest struck at extraction; its originalName is the DOL file name. A published PDF is described once: where a later version acquires a published PDF whose SHA-512 equals that of one already described, no new object is written, and no master is derived from it again except in a master_reconversion version (DPM106); a published PDF whose digest differs is a new object with a new UUID (DPM8). None is written where no master is derived from a published PDF (see *Open items*, conversion skipped). Example: 66a05ffa-9f3c-4f65-a8ed-0eb84c4e31b2, originalName WTGCWT849.pdf | E14: Published PDF file object | F14: 0 (expected 1) | G14: No object for the published Spanish PDF from which the master was derived. | H14: File object without filepath: UUID minted at step 1, SHA-512 and size as extracted, format (PRONOM fmt/276, version 1.7), originalName = DOL file name. | I14: Add a file object for the published Spanish PDF, placed immediately before the master: UUID minted at step 1; no filepath identifier; compositionLevel 0; SHA-512 and size of the PDF as extracted from DOL; format as DROID reports it (expected Acrobat PDF 1.7 - Portable Document Format, 1.7, fmt/276); originalName = its DOL file name. Its UUID and digest already exist in the QA report source block: file_id 585992a9-deba-427d-9360-fce164e33a16, SHA-512 9986bff4d613… (the _src.pdf working copy, a byte copy of the published PDF). | J14: Non-conformance | K14: None — fixable now | L14: EG / implementation | M14: In progress | N14: 2026-10-15 implementation response: Published DOL PDFs remain described by UUID/fixity/size/format/originalName without filepath, before derivation links to masters.
A15: F014 | B15: File | C15: DPM43 | D15: DPM43 Composition level [MUST, 1..1] object/objectCharacteristics/compositionLevel Set to 0. | E15: objectCharacteristics/compositionLevel | F15: 8 file objects | G15: Absent. | H15: 0. | I15: Add <compositionLevel>0</compositionLevel> as the first child of objectCharacteristics on every file object. | J15: Non-conformance | K15: None — fixable now | L15: EG / implementation | M15: In progress | N15: 2026-10-15 implementation response: compositionLevel=0 on every file object.
A16: F015 | B16: File | C16: DPM47 | D16: DPM47 Fixity originator [MUST, 1..1] object/objectCharacteristics/fixity/messageDigestOriginator The agent-registry UUID of the agent that calculated the digest: where the file has a digest calculation event (DPM103), that event's executing program; otherwise the stage script that wrote the file and computed its digest before bagging. The agent is described in the PREMIS file (DPM78). Example: the UUID of [SCRIPT-STEP-1] for a file extracted from DOL; of [SCRIPT-STEP-4] for a veraPDF report it wrote | E16: fixity/messageDigestOriginator | F16: 8 file objects | G16: Absent. | H16: Agent-registry UUID of the agent that calculated the digest (the executing program of DPM103 where there is one); agent described in the file. | I16: Add <messageDigestOriginator>[AGENT-UUID]</messageDigestOriginator> after messageDigest in each fixity: the agent-registry UUID of the executing program of the file's digest calculation event (DPM103) where it has one (DOCX, published PDF, master); otherwise the stage script that wrote the file and computed its digest (reports, conversion log, DROID report, DOME, dome_sql_extraction.json). Needs the agent registry. | J16: Non-conformance | K16: Agent registry | L16: EG / implementation | M16: In progress | N16: 2026-10-15 implementation response: Digest originators reference configured software-agent UUIDs. Provisional agent registry supplied; production registry pending.
A17: F016 | B17: File | C17: DPM49–DPM55 | D17: DPM49 File format [MUST, 1..1] object/objectCharacteristics/format One format per file object, from the format identification of the version that adds the file (DPM109), recorded with both the format designation and the format registry. Where DROID returns no identification or more than one, the item is held for review; the operator's resolution is recorded in the format identification event's outcome detail note (DPM7, DPM109). Two files the pipeline writes itself in a fixed format are recorded without identification: the DROID report, Comma Separated Values, PRONOM x-fmt/18; and the DOME record, Extensible Markup Language 1.0, PRONOM fmt/101. DPM50 File format name grouping [MUST, 1..1] object/objectCharacteristics/format/formatDesignation Always written, together with the registry grouping (DPM53). DPM51 File format name [MUST, 1..1] …/formatDesignation/formatName The PRONOM format name as reported by DROID. Example: Acrobat PDF/A - Portable Document Format DPM52 File format version [MUST where PRONOM gives one, 0..1] …/formatDesignation/formatVersion The PRONOM format version, where PRONOM gives one for the identified format; absent otherwise. Example: 2b DPM53 File format registry grouping [MUST, 1..1] object/objectCharacteristics/format/formatRegistry Always written, together with the name grouping (DPM50). DPM54 File format registry name [MUST, 1..1] …/formatRegistry/formatRegistryName Set to PRONOM. DPM55 File format registry key [MUST, 1..1] …/formatRegistry/formatRegistryKey The PUID reported by DROID. Example: fmt/477 (PDF/A-2b) | E17: objectCharacteristics/format | F17: 7 file objects (all but the DOCX) | G17: formatName is a MIME type or label (application/pdf, application/json, text/xml, XML, application/vnd.ms-excel); no formatRegistry. | H17: PRONOM name and version as reported by DROID, formatRegistryName PRONOM, PUID as key. Expected: master fmt/477 version 2b; veraPDF report, conversion log and DOME fmt/101 version 1.0; QA report fmt/817; DROID report x-fmt/18 (Comma Separated Values, not Excel). | I17: Take the format from the DROID report, not from MIME types: formatDesignation (formatName, formatVersion where PRONOM gives one) and formatRegistry (PRONOM, PUID, role specification). Expected here: master Acrobat PDF/A - Portable Document Format, 2b, fmt/477; veraPDF report Extensible Markup Language, 1.0, fmt/101; DOME the same values, written as fixed values without DROID identification (DPM49); QA report and dome_sql_extraction.json JSON Data Interchange Format, fmt/817; DROID report Comma Separated Values, x-fmt/18; conversion log Extensible Markup Language, 1.0, fmt/101 (Aspose's XML compliance log; F027). Requires DROID to identify every file other than DOME (F046). Workflow tab: W05. | J17: Non-conformance | K17: None — fixable now | L17: EG / implementation | M17: In progress | N17: 2026-10-15 implementation response: Uses DROID identifications, not MIME labels. Optional PoC6 --java/--droid-jar identifies new derived files. Missing PUIDs are explicit draft gaps; strict mode rejects them. DOME has fixed XML format.
... A38: F037 | B38: Event | C38: Element order | D38: Element order (Placement and file model) Element order. The PREMIS 3.0 schema fixes the entity sequence: objects, then events, then agents, then rights. Within each, elements carried from the predecessor keep their place, and the elements a version adds follow them (DPM4), so that each version's file begins with its predecessor's elements, entity by entity. Within the elements one version adds: objects by intellectual entity, then representations, then files in logical-path order, a published PDF (which has no logical path, DPM40) immediately before the master derived from it; events in chronological order; agents in order of first reference. A relationship added to an existing object follows that object's existing relationships (DPM4). The order carries no semantics; it exists so that two correct writers produce comparable files, and so that a version's additions can be checked as an extension of its predecessor. | E38: Sequence of events | F38: 1 | G38: Not chronological: format identification (13:10:38) is listed after QA (13:10:50). | H38: Events in chronological order. | I38: Sort events by eventDateTime before writing. Fix F031 and F047 first, or the sort uses inconsistent times. | J38: Non-conformance | K38: None — fixable now | L38: EG / implementation | M38: In progress | N38: 2026-10-15 implementation response: Events sorted chronologically; predecessor entities preserved.
A39: F038 | B39: Event | C39: DPM102 | D39: DPM102 Ingestion start [MUST, 1..1 per AIP] event[eventType='ingestion start'] Written once per AIP, in v1: by the run that first acquires a language version for a JOB_ID with no AIP, and mints the object's UUID. Not repeated in later versions. Linked object: the intellectual entity. Side: preparation. | E39: Two ingestion events (4c95ff44-…, bf743e75-…) | F39: 2 | G39: Two ingestion events with identical time, detail and outcome, both linking ec1921e0-…, the intellectual entity mistyped as a representation (F006): the target is right, the type and the duplication are wrong. | H39: One ingestion start event, linking the IE, in v1 only. | I39: None (merged into F039). | J39: Non-conformance | K39: — | M39: Closed | N39: Merged into F039 (2026-10-12): both findings described the same two ingestion events. No separate action. 2026-10-15 implementation response: Original review closure/profile issue retained; no implementation closure asserted.
A40: F039 | B40: Event | C40: DPM102, DPM103, DPM104 | D40: DPM102 Ingestion start [MUST, 1..1 per AIP] event[eventType='ingestion start'] Written once per AIP, in v1: by the run that first acquires a language version for a JOB_ID with no AIP, and mints the object's UUID. Not repeated in later versions. Linked object: the intellectual entity. Side: preparation. | E40: Two ingestion events (4c95ff44-…, bf743e75-…) | F40: 2 | G40: Two events of type ingestion, identical but for their UUID: same time (13:10:11.379381Z), executing program Python DPR PoC1, detail and outcome 'STEP_1_PREPARED_FIXITY_VERIFIED', both linking ec1921e0-…, the intellectual entity mistyped as a representation (F006). They are one per extracted file (DOCX, published PDF), recording PoC 1's result, but neither links its file. No ingestion start is written. | H40: One ingestion start in v1 only, linking the intellectual entity (DPM102); per extracted file, a digest calculation and a copy fixity verification linking that file (DPM103, DPM104). | I40: Replace the two ingestion events: write one ingestion start event when the object is created (v1), linking [OBJECT-UUID], first detail ingestion start (DPM102); and for each extracted file (DOCX, published PDF) a message digest calculation and a fixity check event linking that file's UUID (DPM103, DPM104; F040). | J40: Non-conformance | K40: None — fixable now | L40: EG / implementation | M40: In progress | N40: F038 merged into this finding (2026-10-12): both described the same two ingestion events. 2026-10-15 implementation response: One ingestion start for first object version; distinct digest and fixity events per received source.
A41: F040 | B41: Event | C41: DPM103, DPM104 | D41: DPM103 Digest calculation [MUST, 1 per extracted file and per master] event[eventType='message digest calculation'] The SHA-512 struck on a file when it first exists in the pipeline: on each rep_1 file and each published PDF as extracted from DOL, and on each master as created. Its executing program is the file's fixity originator (DPM47). Linked object: the file. Side: preparation. DPM104 Copy fixity verification [MUST, 1 per extracted file] event[eventType='fixity check'] The copy out of DOL re-hashed and verified against its digest calculation (DPM103). Linked object: the file (for a published PDF, the object describing it). Side: preparation. | E41: Digest calculation; copy fixity verification | F41: 0 | G41: Absent (possibly folded into the ingestion events). | H41: DPM103 and DPM104 per extracted file (DOCX, published PDF); DPM103 on the master as created. | I41: For the DOCX and the published PDF: one message digest calculation event and one fixity check event each, linking the file's UUID. For the master: one message digest calculation event when created. | J41: Non-conformance | K41: None — fixable now | L41: EG / implementation | M41: In progress | N41: 2026-10-15 implementation response: Digest/fixity events on received files; digest event on masters; stable event keys prevent duplicate history.
A42: F041 | B42: Event | C42: DPM105 | D42: DPM105 Filename change [MUST, 1 per renamed held file] event[eventType='filename change'] A held file renamed from its DOL name to its canonical name (Placement and file model, Canonical names). Linked object: the file. Side: preparation. | E42: Filename change | F42: 0 | G42: Absent. | H42: One per held file renamed from its DOL name (the DOCX). | I42: Add one filename change event linking the DOCX UUID, renamed from its DOL name. | J42: Non-conformance | K42: None — fixable now | L42: EG / implementation | M42: In progress | N42: 2026-10-15 implementation response: Filename change event for renamed source files.
A43: F042 | B43: Event | C43: DPM106 | D43: DPM106 Normalisation [MUST, 1 per converted master] event[eventType='normalization'] Conversion of a published PDF to its PDF/A preservation master by the WTO conversion program. Linked objects: the published PDF (source), the master (outcome) and, where one is held, the conversion log (outcome). Executing program: the conversion engine, Aspose.PDF for C++ (DPM57). Event detail: target_level: PDF/A-2b. Outcome detail note: the alterations and removals reported by the engine, or none. In a master_reconversion version, further details: supersedes: <UUID>, the master replaced; reason: <the defect found>; and, where a conversion parameter was changed, parameter: <name>: <value>. Not written where conversion was skipped (see *Open items*). Side: preparation. Example: target_level: PDF/A-2b | E43: Normalization (d4a0ea3f-…) | F43: 1 | G43: Links the master only, without role; no target_level detail; no outcome note. | H43: Published PDF as source; master and the held conversion log as outcome; detail target_level: PDF/A-2b; outcome note the engine's reported alterations, or none. | I43: Normalisation event: linkingObjectIdentifier published PDF UUID with role source, master UUID with role outcome, conversion log UUID with role outcome (DPM106, F056); eventDetailInformation target_level: PDF/A-2b; eventOutcomeDetailNote with the engine's reported alterations, or none. | J43: Non-conformance | K43: None — fixable now | L43: EG / implementation | M43: In progress | N43: 2026-10-15 implementation response: Normalization links source, master and retained conversion log; target detail retained. Alteration-detail extraction from actual Aspose log is not implemented; skipped conversion is not falsely called normalization.
A44: F043 | B44: Event | C44: DPM58, DPM106 | D44: DPM58 Name of creating application [MUST, 1..1] …/creatingApplication/creatingApplicationName The engine's vendor and product edition, as registered in the agent registry; the same as the agentName of the engine agent, the executing program of the normalisation event (DPM106). The edition is part of the identity: the .NET, Java and C++ editions of Aspose.PDF are distinct products. Example: Aspose.PDF for C++ DPM106 Normalisation [MUST, 1 per converted master] event[eventType='normalization'] Conversion of a published PDF to its PDF/A preservation master by the WTO conversion program. Linked objects: the published PDF (source), the master (outcome) and, where one is held, the conversion log (outcome). Executing program: the conversion engine, Aspose.PDF for C++ (DPM57). Event detail: target_level: PDF/A-2b. Outcome detail note: the alterations and removals reported by the engine, or none. In a master_reconversion version, further details: supersedes: <UUID>, the master replaced; reason: <the defect found>; and, where a conversion parameter was changed, parameter: <name>: <value>. Not written where conversion was skipped (see *Open items*). Side: preparation. Example: target_level: PDF/A-2b | E44: Normalization executing program | F44: 1 | G44: Aspose.PDF for .NET. | H44: Profile specifies Aspose.PDF for C++, and the edition is part of the agent's identity. Confirm which edition the PoC uses; correct the label or the profile. | I44: Developer: confirm which Aspose edition the conversion program uses. If C++, correct the label. If .NET, tell the profile owner so DPM57 and DPM58 change. | J44: Suspected defect | K44: Engine identity (edition and version) | L44: EG / implementation | M44: In progress | N44: 2026-10-15 implementation response: Confirmed from .csproj and Program.cs: Aspose.PDF for .NET, package 25.10.0. Propose correcting profile C++ references.
A45: F044 | B45: Event | C45: DPM107 | D45: DPM107 Conformance validation [MUST, 1 per master] event[eventType='validation'] The passing veraPDF validation of a master. Linked objects: the master (source), the veraPDF report (outcome). Executing program: veraPDF. Event detail: validation_profile: PDF/A-2B, the veraPDF profile applied; its version is that of the veraPDF agent (DPM84). Outcome detail note: the accepted warnings, reviewer and reason, where warnings were accepted. Side: preparation. Example: validation_profile: PDF/A-2B | E45: Validation (f0af495b-…) | F45: 1 | G45: Links the master only, without role; no report; no validation_profile. | H45: Master as source, veraPDF report as outcome; detail validation_profile: PDF/A-2B. | I45: Validation event: master UUID with role source, veraPDF report UUID with role outcome; eventDetail validation_profile: PDF/A-2B. | J45: Non-conformance | K45: None — fixable now | L45: EG / implementation | M45: In progress | N45: 2026-10-15 implementation response: Validation source/outcome UUIDs and validation_profile: PDF/A-2B.
A46: F045 | B46: Event | C46: DPM108 | D46: DPM108 Fidelity review [MUST, 1 per converted master] event[eventType='qualityReview'] The accepting QA decision on a master's fidelity to its source. Local event type (no LoC equivalent; see *Open items* for its namespace). Linked objects: the master (source), the QA report (outcome). Executing program: the QA stage script ([SCRIPT-STEP-5]), whose tagged release pins the comparison libraries it uses (pypdf, pdfminer.six); where sampled for manual review, also the reviewer as implementer. Event detail: sampled: true or false. Outcome detail note: the adjudicated reason for any flagged difference. Side: preparation. Example: sampled: false | E46: Quality assurance (2f108447-…) | F46: 1 | G46: Type quality assurance; links the master only; no sampled detail; no report. | H46: Type qualityReview (local); master as source, QA report as outcome; detail sampled: true or false. | I46: Event type qualityReview with authority="local"; master UUID with role source, QA report UUID with role outcome; eventDetail sampled: false (or true). | J46: Non-conformance | K46: None — fixable now | L46: EG / implementation | M46: In progress | N46: 2026-10-15 implementation response: Local qualityReview, master source, QA report outcome, sampled:false. Manual adjudication workflow remains outside this implementation.
A47: F046 | B47: Event | C47: DPM109 | D47: DPM109 Format identification [MUST, 1 per version that adds a file object other than a DOME record] event[eventType='format identification'] The identification of the files in this version's SIP, other than the DOME record (DPM49), together with the published PDFs of its new masters, which are identified in the same run but not held. DROID runs per batch; its report is generated per JOB_ID, so each package holds only its own results. Written per object. Linked objects: each file object identified (no role); the DROID report for this JOB_ID (outcome), which also lists the published PDFs (DPM40). Executing program: DROID, its version including the signature file (DPM84). Event detail: batch_id: <UUID>. Outcome detail note: the operator's resolution of any file DROID could not identify uniquely (DPM49). Side: preparation. Example: batch_id: 3113aa86-311d-441f-a39b-08ba19065b9e; outcome the DROID report at documentation/2026_012017_ff_droid.csv | E47: Format identification (d5f4e12d-…) | F47: 1 | G47: Links 2 of 8 files; no DROID report as outcome; no batch_id. | H47: Every file object identified in the version other than DOME and the DROID report itself (and including the published PDF), DROID report as outcome; detail batch_id: <UUID>. | I47: Run DROID over every file in the version except DOME (DPM49) plus the published PDF. Link each file object (UUID, no role) and the DROID report (role outcome); eventDetail batch_id: [BATCH-UUID]. | J47: Non-conformance | K47: None — fixable now | L47: EG / implementation | M47: In progress | N47: 2026-10-15 implementation response: Optional post-conversion DROID includes new derived evidence and sources; full identification requires installed tool/signature configuration. Strict mode blocks missing PUIDs.
A48: F047 | B48: Event | C48: DPM109 | D48: DPM109 Format identification [MUST, 1 per version that adds a file object other than a DOME record] event[eventType='format identification'] The identification of the files in this version's SIP, other than the DOME record (DPM49), together with the published PDFs of its new masters, which are identified in the same run but not held. DROID runs per batch; its report is generated per JOB_ID, so each package holds only its own results. Written per object. Linked objects: each file object identified (no role); the DROID report for this JOB_ID (outcome), which also lists the published PDFs (DPM40). Executing program: DROID, its version including the signature file (DPM84). Event detail: batch_id: <UUID>. Outcome detail note: the operator's resolution of any file DROID could not identify uniquely (DPM49). Side: preparation. Example: batch_id: 3113aa86-311d-441f-a39b-08ba19065b9e; outcome the DROID report at documentation/2026_012017_ff_droid.csv | E48: Format identification timing | F48: 1 | G48: Timestamped 13:10:38, before the normalisation (13:10:47), and links the master path. By design DROID runs before conversion and identifies the _src PDF, not the master (Workflow Documentation v2.5 §4.6; the DROID CSV lists the DOCX, fmt/412, and the _src PDF, fmt/276). The event therefore links an object DROID never read, and the master is never identified. | H48: The event links the files DROID identified: the authoring source and the published PDF (DPM40), not the master; the master is identified after normalisation (fmt/477, DPM49). | I48: Developer: link the DROID event to the objects DROID read (the DOCX and the published PDF object, F013); identify the master after conversion and record its PUID (F016). Workflow tab: W05. | J48: Non-conformance | K48: None — fixable now | L48: EG / implementation | M48: In progress | N48: 2026-10-15 implementation response: Source-only DROID links received source IDs; optional post-conversion identification adds master/evidence IDs. Review still needed for skipped-conversion characterization semantics.
A49: F048 | B49: Event | C49: DPM116 | D49: DPM116 Descriptive metadata creation [MUST, 1..1 per AIP] event[eventType='creation'] The object's first DOME record, written in v1. Linked objects: the intellectual entity (no role); the DOME file (outcome). Executing program: the DOME script. Event detail: cat_header_id: <value>, the DOL catalogue record ID (CatHeaderId) from which the DOME record was built, through which DOL links the metadata fields used; DOME does not contain it, so this is its only record in the package. Side: preparation. Example: cat_header_id: [DOL-RECORD-ID] | E49: DOME event | F49: 0 | G49: Absent. | H49: For the first DOME record (v1): a descriptive metadata creation event (DPM116), linking the intellectual entity (no role) and the DOME file (outcome), with event detail cat_header_id. | I49: Add a creation event (eventType creation, @valueURI http://id.loc.gov/vocabulary/preservation/eventType/cre; first detail descriptive metadata creation (DPM116); second detail cat_header_id: <DOL CatHeaderId>) linking [OBJECT-UUID] without role and the DOME file UUID with role outcome; executing program the DOME script, authorizer the operator. | J49: Non-conformance | K49: None — fixable now | L49: EG / implementation | M49: In progress | N49: 2026-10-15 implementation response: DOME creation links IE and DOME output with CatHeaderId now selected from SQL. Missing CatHeaderId is a draft gap.
A50: F049 | B50: Event | C50: DPM111 | D50: DPM111 SIP creation [MUST, 1..1 per version created from a SIP] event[eventType='information package creation'] The SIP built at step 7; the last event written on the preparation side. Linked object: the intellectual entity. Event details, each in its own eventDetailInformation: sip_id: <UUID>, the SIP's own UUID (DPM8, DPM23); selection_basis: <value>, from vocODRNSSelectionBasis (see *Controlled vocabularies*); batch_id: <UUID>; languages: <language codes>, the language versions held in the version once committed, comma-separated (e.g. en, es); for a re-issue or a master reconversion, changed_languages: <language codes>. Outcome detail note: package type: SIP. Side: preparation. Example: sip_id: 8db4332b-de6e-4322-bbb6-3e9e5629bc19; selection_basis: new_document; batch_id: 3113aa86-311d-441f-a39b-08ba19065b9e; languages: en | E50: SIP creation | F50: 0 | G50: Absent. | H50: Last preparation-side event, linking the IE; details sip_id, selection_basis (new_document), batch_id, languages: es; note package type: SIP. | I50: Add the SIP creation event as the last preparation-side event: eventType information package creation; linked object [OBJECT-UUID]; details sip_id: [SIP-UUID], selection_basis: new_document, batch_id: [BATCH-UUID], languages: es; outcome success with note package type: SIP. Workflow tab: W10. | J50: Non-conformance | K50: None — fixable now | L50: EG / implementation | M50: In progress | N50: 2026-10-15 implementation response: SIP creation last on preparation side, sip_id/batch_id/languages/selection_basis details. Selection is proposed from byte/language differences or explicit CLI override; LastDmsAction semantics pending.
A51: F050 | B51: Event | C51: DPM112, DPM113, DPM117 | D51: DPM112 Ingest fixity verification [MUST, 1..1 per version created from a SIP] event[eventType='fixity check'] The bag verified against its SHA-512 manifest on receipt at step 8 (verified outcome only). Linked object: the intellectual entity. Event details, each in its own eventDetailInformation: sip_id: <UUID>, the SIP whose bag was verified (as in DPM111); package_manifest: manifest-sha512.txt. Outcome detail note: the bag's Payload-Oxum. Side: ingest. Example: sip_id: 8db4332b-de6e-4322-bbb6-3e9e5629bc19; outcome detail note Payload-Oxum: 1468230.7 DPM113 AIP creation [MUST, 1..1 per version] event[eventType='information package creation'] The AIP version written to OCFL at step 9. Linked object: the intellectual entity, whose UUID also names the AIP (DPM23). Event detail: ocfl_version: vN. Outcome detail note: package type: AIP. Its authorizer and time agree with the version's commit record (DPM14). Side: ingest. Example: ocfl_version: v1 DPM117 PREMIS of the AIP version [MUST, 1..1 per AIP version created from a SIP] metadata/preservation/{JOB_ID}_premis.xml as committed at step 9 The premis.xml committed in an AIP version created from a SIP is the SIP's premis.xml with exactly these additions, appended by the ingest side: the ingest fixity verification event (DPM112), the AIP creation event (DPM113), and a description of each executing program of those two events not already described (DPM78). Nothing else differs from the SIP's file. It is the file read as the predecessor by the next version (DPM2). | E51: Ingest fixity verification; AIP creation | F51: 0 | G51: Absent. The file is the AIP's PREMIS: it is metadata/2026_011922_premis.xml in the v1 state of the OCFL inventory (SHA-512 0563f1ff…, identical to the file reviewed). v1 was committed 2026-10-09T13:10:59Z without the ingest side's events. | H51: Appended by the ingest side before commit: ingest fixity verification (DPM112) and AIP creation (DPM113, ocfl_version: v1), and a description of the ingest software agent (DPM117). | I51: Ingest side: after bag verification, parse the SIP's PREMIS and append DPM112 and DPM113 with the ingest software agent; validate (DPM10) and run the DPM14 checks before commit. Since v1 was committed without them, those checks are not implemented: a failure must hold the bag and commit nothing (DPM3). | J51: Non-conformance | K51: None — fixable now | L51: EG / implementation | M51: In progress | N51: 2026-10-15 implementation response: Ingest copies SIP into workspace, appends DPM112 and DPM113 plus agent descriptions, validates schemas and agreement before OCFL commit. Received bag remains byte-identical.
... A55: F054 | B55: Agent | C55: Element order | D55: Element order (Placement and file model) Element order. The PREMIS 3.0 schema fixes the entity sequence: objects, then events, then agents, then rights. Within each, elements carried from the predecessor keep their place, and the elements a version adds follow them (DPM4), so that each version's file begins with its predecessor's elements, entity by entity. Within the elements one version adds: objects by intellectual entity, then representations, then files in logical-path order, a published PDF (which has no logical path, DPM40) immediately before the master derived from it; events in chronological order; agents in order of first reference. A relationship added to an existing object follows that object's existing relationships (DPM4). The order carries no semantics; it exists so that two correct writers produce comparable files, and so that a version's additions can be checked as an extension of its predecessor. | E55: Sequence of agents | F55: 5 agents | G55: Alphabetical. | H55: In order of first reference. | I55: Write agents in order of first reference in the events, not alphabetically. | J55: Non-conformance | K55: None — fixable now | L55: EG / implementation | M55: In progress | N55: 2026-10-15 implementation response: Agents emitted at first event/fixity reference; predecessor order retained. Digest-originator references may precede event reference and need profile-owner confirmation.
